Workbook

Sheet Read me
A1: MedSim VRAI — Field Test Matrix
A2: How to run | B2: Work the 'Test Matrix' sheet area by area. Set Result (Pass / Fail / Blocked / Not run / N-A), initials, date, Notes. Leave NO P1 row 'Not run' before sign-off.
A3: Priorities | B3: P1 must pass before broader rollout · P2 important · P3 edge. The Device(s) column shows the hardware each test needs.
A4: When a test fails | B4: Add a row to 'Issue Log': Title, Steps to reproduce, Expected, Actual, Environment, Severity, link the Test ID, Status = New.
A5: ➜ Feeding issues to Claude | B5: The Issue Log columns are ORDERED to give Claude full context. To get a fix: filter Status = New, copy the rows (incl. header), paste into Claude Code with 'Fix these field-test issues:' + paste. Claude triages, fixes, gates, and replies with the commit; set Status Fixed → Verified after you retest.
A6: Coverage | B6: The 'Coverage' sheet rolls up Pass/Fail per area (live formulas) so gaps are visible. 'Environment' tracks the tablets/OS/browsers used.
A7: Pre-flight | B7: Run scripts/preflight.sh (6/6) before any tablet session. Area A (network/cert) gates everything else.
A8: Status at generation | B8: FR-008 staged errors: the arm→missed→debrief arc is already field-validated (test H11). Everything else awaits this matrix.

Sheet Test Matrix
A1: Test ID | B1: Area | C1: Pri | D1: Test case | E1: Preconditions | F1: Steps | G1: Expected result | H1: Device(s) | I1: Result | J1: Tester | K1: Date | L1: Notes
A2: A · Network & pairing (FR-004)
A3: A1 | B3: A | C3: P1 | D3: Preflight passes 6/6 | E3: Mac on session network | F3: Run scripts/preflight.sh | G3: All 6 checks green; QR minted; onboarding URL printed | H3: Mac
A4: A2 | B4: A | C4: P1 | D4: Cert SAN covers current IP | E4: Network identity known | F4: Preflight check 3 / cert-doctor.sh | G4: Leaf cert SAN includes the Mac's current LAN IP | H4: Mac
A5: A3 | B5: A | C5: P1 | D5: Root CA trusted on each tablet | E5: CA installed once per device | F5: Open https portal on tablet | G5: Green lock, NO cert warning, getUserMedia allowed | H5: iPad,Android
A6: A4 | B6: A | C6: P2 | D6: Onboarding page loads on a NEW tablet | E6: Fresh tablet, CA not trusted | F6: Scan QR → proceed → /onboard → install CA | G6: Page renders; CA downloads + installs; lock turns green | H6: iPad,Android
A7: A5 | B7: A | C7: P1 | D7: Travel-router (Beryl) full loop | E7: Tablets on Beryl, MAC-privacy OFF | F7: Run a full voice take over the kit LAN | G7: Loop completes; NO new trust step (CA holds across networks) | H7: iPad,Android
A8: A6 | B8: A | C8: P2 | D8: Mac IP stable across restart | E8: Static DHCP lease bound | F8: Restart router/Mac; recheck IP | G8: Mac keeps the same IP; QR/cert still valid | H8: Mac
A9: B · Avatar tablet (FR-006)
A10: B1 | B10: B | C10: P1 | D10: Patient QR → 3D face loads | E10: Patient persona, avatar mode | F10: Scan patient QR | G10: Translucent 3D face renders; no console errors | H10: iPad
A11: B2 | B11: B | C11: P1 | D11: Lip-sync tracks speech | E11: Avatar live | F11: Trigger a spoken reply | G11: Visemes track the audio; no desync | H11: iPad
A12: B3 | B12: B | C12: P2 | D12: Emotion / altered-state reflected | E12: Persona w/ emotion state | F12: Drive a turn with emotion | G12: Expression reflects the persona's state | H12: iPad
A13: B4 | B13: B | C13: P3 | D13: Translucency slider works | E13: Avatar live | F13: Drag the slider | G13: Opacity changes smoothly | H13: iPad
A14: B5 | B14: B | C14: P2 | D14: Reconnect after network blip | E14: Avatar live | F14: Drop + restore Wi-Fi | G14: WS reconnects; avatar resumes without reload | H14: iPad
A15: C · Audio station (FR-006b)
A16: C1 | B16: C | C16: P1 | D16: Audio QR → flat portrait (no 3D) | E16: Non-patient, audio mode | F16: Scan audio-mode QR | G16: Flat portrait + name + badge; NO 3D rig | H16: Android
A17: C2 | B17: C | C17: P1 | D17: Push-to-talk records | E17: Audio station up | F17: Hold, speak, release | G17: Recording captured; transcription begins | H17: Android
A18: C3 | B18: C | C18: P1 | D18: Room-local STT (Mac) transcribes | E18: Portal up, STT warm | F18: One spoken take | G18: Transcript in ~1–2 s; character replies in voice | H18: Android,Mac
A19: C4 | B19: C | C19: P2 | D19: Drug names transcribe correctly | E19: Med board active | F19: Say an order w/ a drug name | G19: Drug name faithful (e.g. 'ceftriaxone') | H19: Android,Mac
A20: C5 | B20: C | C20: P3 | D20: Name shows (not internal ID) | E20: Bound character | F20: Read the header | G20: Persona name (e.g. 'Pharmacist Lee') | H20: Android
A21: C6 | B21: C | C21: P2 | D21: On-device backup if portal drops | E21: Portal unreachable | F21: Take after drop | G21: Names the failure + arms on-device fallback | H21: Android
A22: D · Voice loop end-to-end
A23: D1 | B23: D | C23: P1 | D23: Full loop PTT→STT→AI→TTS | E23: Character bound, running | F23: One complete take | G23: Speech → transcript → character voice reply | H23: iPad,Android
A24: D2 | B24: D | C24: P1 | D24: First words within target | E24: Warm session | F24: Time a reply | G24: First audio ~2–3 s (streaming) | H24: iPad,Android
A25: D3 | B25: D | C25: P2 | D25: iPad on-device STT (WebGPU) | E25: iPad avatar | F25: Take on iPad | G25: On-device whisper (~1–1.5 s warm) | H25: iPad
A26: D4 | B26: D | C26: P2 | D26: Several takes in a row | E26: Warm session | F26: 5 takes back-to-back | G26: Consistent latency; no degradation | H26: iPad,Android
A27: E · Control room (FR-005)
A28: E1 | B28: E | C28: P1 | D28: Setup page renders all cards | E28: Logged in, configured | F28: Open /portal/control/setup | G28: Med, devices, skins/voices, add-character present | H28: Mac
A29: E2 | B29: E | C29: P1 | D29: START opens Live Ops window | E29: On Setup | F29: Press ▶ START | G29: Goes live; Live Operations opens in a NEW window | H29: Mac
A30: E3 | B30: E | C30: P2 | D30: Add character mid-session | E30: Live session | F30: Add a persona via banner | G30: Character appears + becomes scannable | H30: Mac
A31: E4 | B31: E | C31: P2 | D31: Avatar ⇄ audio toggle | E31: Setup/Live | F31: Flip a character's mode | G31: QR re-mints for the chosen mode | H31: Mac
A32: E5 | B32: E | C32: P3 | D32: Configured session lands on Setup | E32: Configured | F32: Navigate to /ops directly | G32: Redirects to Setup | H32: Mac
A33: F · Say-as-character (FR-003)
A34: F1 | B34: F | C34: P1 | D34: Verbatim mode | E34: Character bound | F34: Say-as: verbatim line | G34: Character speaks the exact text | H34: iPad,Android
A35: F2 | B35: F | C35: P1 | D35: In-character mode | E35: Character bound | F35: Say-as: in-character intent | G35: AI rephrases in persona voice/emotion | H35: iPad,Android
A36: G · Med ordering (FR-001/002)
A37: G1 | B37: G | C37: P1 | D37: Doctor orders decisively WITH dose | E37: Doctor, condition set | F37: Ask the doctor for orders | G37: Doctor PLACES an order w/ a full dose; no 'what's available' | H37: iPad,Android
A38: G2 | B38: G | C38: P2 | D38: Doctor escalates if already-on | E38: Patient already on primary | F38: Ask again | G38: Doctor picks a different primary / escalates | H38: iPad,Android
A39: G3 | B39: G | C39: P1 | D39: Instructor flags a med unavailable | E39: Med board open | F39: Toggle a med unavailable | G39: Med marked unavailable in board state | H39: Mac
A40: G4 | B40: G | C40: P1 | D40: Pharmacist coaches an alternative | E40: Med flagged unavailable | F40: Ask the pharmacist | G40: Names an AUTHORED alternative (never invented) | H40: Android
...

Sheet Issue Log
A1: Issue ID | B1: Test ID | C1: Area | D1: Severity | E1: Title | F1: Steps to reproduce | G1: Expected | H1: Actual | I1: Environment (device/OS/browser/network) | J1: Status | K1: Date found | L1: Resolution / commit
A2: ISS-001 | B2: H7 | C2: Staged errors | D2: Medium | E2: (EXAMPLE) Stabilize left the symptom prompt active | F2: Arm allergy error w/ moderate impact; Trigger; then Stabilize | G2: Patient returns to baseline AND symptom prompt clears | H2: Vitals reverted but the character mentioned itching one more turn | I2: iPad Safari 26 / Beryl LAN | J2: New | K2: 2026-06-13

Sheet Coverage
A1: Area | B1: Tests | C1: Pass | D1: Fail | E1: Blocked | F1: Not run | G1: % pass
A2: A · Network & pairing (FR-004) | B2: =COUNTIF('Test Matrix'!$B:$B,"A") | C2: =COUNTIFS('Test Matrix'!$B:$B,"A",'Test Matrix'!$I:$I,"Pass") | D2: =COUNTIFS('Test Matrix'!$B:$B,"A",'Test Matrix'!$I:$I,"Fail") | E2: =COUNTIFS('Test Matrix'!$B:$B,"A",'Test Matrix'!$I:$I,"Blocked") | F2: =COUNTIFS('Test Matrix'!$B:$B,"A",'Test Matrix'!$I:$I,"Not run") | G2: =IF(B2=0,0,C2/B2)
A3: B · Avatar tablet (FR-006) | B3: =COUNTIF('Test Matrix'!$B:$B,"B") | C3: =COUNTIFS('Test Matrix'!$B:$B,"B",'Test Matrix'!$I:$I,"Pass") | D3: =COUNTIFS('Test Matrix'!$B:$B,"B",'Test Matrix'!$I:$I,"Fail") | E3: =COUNTIFS('Test Matrix'!$B:$B,"B",'Test Matrix'!$I:$I,"Blocked") | F3: =COUNTIFS('Test Matrix'!$B:$B,"B",'Test Matrix'!$I:$I,"Not run") | G3: =IF(B3=0,0,C3/B3)
A4: C · Audio station (FR-006b) | B4: =COUNTIF('Test Matrix'!$B:$B,"C") | C4: =COUNTIFS('Test Matrix'!$B:$B,"C",'Test Matrix'!$I:$I,"Pass") | D4: =COUNTIFS('Test Matrix'!$B:$B,"C",'Test Matrix'!$I:$I,"Fail") | E4: =COUNTIFS('Test Matrix'!$B:$B,"C",'Test Matrix'!$I:$I,"Blocked") | F4: =COUNTIFS('Test Matrix'!$B:$B,"C",'Test Matrix'!$I:$I,"Not run") | G4: =IF(B4=0,0,C4/B4)
A5: D · Voice loop end-to-end | B5: =COUNTIF('Test Matrix'!$B:$B,"D") | C5: =COUNTIFS('Test Matrix'!$B:$B,"D",'Test Matrix'!$I:$I,"Pass") | D5: =COUNTIFS('Test Matrix'!$B:$B,"D",'Test Matrix'!$I:$I,"Fail") | E5: =COUNTIFS('Test Matrix'!$B:$B,"D",'Test Matrix'!$I:$I,"Blocked") | F5: =COUNTIFS('Test Matrix'!$B:$B,"D",'Test Matrix'!$I:$I,"Not run") | G5: =IF(B5=0,0,C5/B5)
A6: E · Control room (FR-005) | B6: =COUNTIF('Test Matrix'!$B:$B,"E") | C6: =COUNTIFS('Test Matrix'!$B:$B,"E",'Test Matrix'!$I:$I,"Pass") | D6: =COUNTIFS('Test Matrix'!$B:$B,"E",'Test Matrix'!$I:$I,"Fail") | E6: =COUNTIFS('Test Matrix'!$B:$B,"E",'Test Matrix'!$I:$I,"Blocked") | F6: =COUNTIFS('Test Matrix'!$B:$B,"E",'Test Matrix'!$I:$I,"Not run") | G6: =IF(B6=0,0,C6/B6)
A7: F · Say-as-character (FR-003) | B7: =COUNTIF('Test Matrix'!$B:$B,"F") | C7: =COUNTIFS('Test Matrix'!$B:$B,"F",'Test Matrix'!$I:$I,"Pass") | D7: =COUNTIFS('Test Matrix'!$B:$B,"F",'Test Matrix'!$I:$I,"Fail") | E7: =COUNTIFS('Test Matrix'!$B:$B,"F",'Test Matrix'!$I:$I,"Blocked") | F7: =COUNTIFS('Test Matrix'!$B:$B,"F",'Test Matrix'!$I:$I,"Not run") | G7: =IF(B7=0,0,C7/B7)
A8: G · Med ordering (FR-001/002) | B8: =COUNTIF('Test Matrix'!$B:$B,"G") | C8: =COUNTIFS('Test Matrix'!$B:$B,"G",'Test Matrix'!$I:$I,"Pass") | D8: =COUNTIFS('Test Matrix'!$B:$B,"G",'Test Matrix'!$I:$I,"Fail") | E8: =COUNTIFS('Test Matrix'!$B:$B,"G",'Test Matrix'!$I:$I,"Blocked") | F8: =COUNTIFS('Test Matrix'!$B:$B,"G",'Test Matrix'!$I:$I,"Not run") | G8: =IF(B8=0,0,C8/B8)
A9: H · Staged errors (FR-008) | B9: =COUNTIF('Test Matrix'!$B:$B,"H") | C9: =COUNTIFS('Test Matrix'!$B:$B,"H",'Test Matrix'!$I:$I,"Pass") | D9: =COUNTIFS('Test Matrix'!$B:$B,"H",'Test Matrix'!$I:$I,"Fail") | E9: =COUNTIFS('Test Matrix'!$B:$B,"H",'Test Matrix'!$I:$I,"Blocked") | F9: =COUNTIFS('Test Matrix'!$B:$B,"H",'Test Matrix'!$I:$I,"Not run") | G9: =IF(B9=0,0,C9/B9)
A10: I · EHR / Medical Records | B10: =COUNTIF('Test Matrix'!$B:$B,"I") | C10: =COUNTIFS('Test Matrix'!$B:$B,"I",'Test Matrix'!$I:$I,"Pass") | D10: =COUNTIFS('Test Matrix'!$B:$B,"I",'Test Matrix'!$I:$I,"Fail") | E10: =COUNTIFS('Test Matrix'!$B:$B,"I",'Test Matrix'!$I:$I,"Blocked") | F10: =COUNTIFS('Test Matrix'!$B:$B,"I",'Test Matrix'!$I:$I,"Not run") | G10: =IF(B10=0,0,C10/B10)
A11: J · Multi-patient / room | B11: =COUNTIF('Test Matrix'!$B:$B,"J") | C11: =COUNTIFS('Test Matrix'!$B:$B,"J",'Test Matrix'!$I:$I,"Pass") | D11: =COUNTIFS('Test Matrix'!$B:$B,"J",'Test Matrix'!$I:$I,"Fail") | E11: =COUNTIFS('Test Matrix'!$B:$B,"J",'Test Matrix'!$I:$I,"Blocked") | F11: =COUNTIFS('Test Matrix'!$B:$B,"J",'Test Matrix'!$I:$I,"Not run") | G11: =IF(B11=0,0,C11/B11)
A12: K · Devices | B12: =COUNTIF('Test Matrix'!$B:$B,"K") | C12: =COUNTIFS('Test Matrix'!$B:$B,"K",'Test Matrix'!$I:$I,"Pass") | D12: =COUNTIFS('Test Matrix'!$B:$B,"K",'Test Matrix'!$I:$I,"Fail") | E12: =COUNTIFS('Test Matrix'!$B:$B,"K",'Test Matrix'!$I:$I,"Blocked") | F12: =COUNTIFS('Test Matrix'!$B:$B,"K",'Test Matrix'!$I:$I,"Not run") | G12: =IF(B12=0,0,C12/B12)
A13: L · Debrief | B13: =COUNTIF('Test Matrix'!$B:$B,"L") | C13: =COUNTIFS('Test Matrix'!$B:$B,"L",'Test Matrix'!$I:$I,"Pass") | D13: =COUNTIFS('Test Matrix'!$B:$B,"L",'Test Matrix'!$I:$I,"Fail") | E13: =COUNTIFS('Test Matrix'!$B:$B,"L",'Test Matrix'!$I:$I,"Blocked") | F13: =COUNTIFS('Test Matrix'!$B:$B,"L",'Test Matrix'!$I:$I,"Not run") | G13: =IF(B13=0,0,C13/B13)
A14: M · Non-functional | B14: =COUNTIF('Test Matrix'!$B:$B,"M") | C14: =COUNTIFS('Test Matrix'!$B:$B,"M",'Test Matrix'!$I:$I,"Pass") | D14: =COUNTIFS('Test Matrix'!$B:$B,"M",'Test Matrix'!$I:$I,"Fail") | E14: =COUNTIFS('Test Matrix'!$B:$B,"M",'Test Matrix'!$I:$I,"Blocked") | F14: =COUNTIFS('Test Matrix'!$B:$B,"M",'Test Matrix'!$I:$I,"Not run") | G14: =IF(B14=0,0,C14/B14)
A15: TOTAL | B15: =SUM(B2:B14) | C15: =SUM(C2:C14) | D15: =SUM(D2:D14) | E15: =SUM(E2:E14) | F15: =SUM(F2:F14) | G15: =IF(B15=0,0,C15/B15)

Sheet Environment
A1: Device / role | B1: Model | C1: OS / browser | D1: IP or join | E1: CA trusted? | F1: Private-MAC OFF? | G1: Notes
A2: Portal (Mac) | C2: macOS | D2: 192.168.x.x | E2: n/a | F2: n/a | G2: run preflight.sh first
A3: Avatar tablet | B3: iPad | C3: Safari 26
A4: Audio station | B4: Android | C4: Chrome
A5: Device station
A6: Router | B6: Beryl AX | D6: 192.168.8.1 | E6: n/a | F6: n/a | G6: bind Mac IP (static lease)
